<mujoco model="x3_zz1">
  <compiler angle="radian" meshdir="./"/>
  <statistic meansize="0.177939" extent="1.9618" center="0.0465088 1.93584e-06 -0.21519"/>
  <default>
    <joint damping="0.1" armature="0.01" frictionloss="0.1"/>
  </default>
  <asset>
    <texture type="skybox" builtin="gradient" width="128" height="128" rgb1="0.4 0.6 0.8" rgb2="0 0 0"/>
    <texture name="plane" type="2d" builtin="checker" rgb1="0.2 0.2 0.2" rgb2="0.3 0.3 0.3" width="512"
              height="512"/>
    <material name="plane" reflectance="0.0" texture="plane" texrepeat="1 1" texuniform="true"/>
    <mesh name="pelvis" content_type="model/stl" file="meshes/pelvis.STL"/>
    <mesh name="left_hip_pitch_link" content_type="model/stl" file="meshes/left_hip_pitch_link.STL"/>
    <mesh name="left_hip_roll_link" content_type="model/stl" file="meshes/left_hip_roll_link.STL"/>
    <mesh name="left_hip_yaw_link" content_type="model/stl" file="meshes/left_hip_yaw_link.STL"/>
    <mesh name="left_knee_link" content_type="model/stl" file="meshes/left_knee_link.STL"/>
    <mesh name="left_ankle_pitch_link" content_type="model/stl" file="meshes/left_ankle_pitch_link.STL"/>
    <mesh name="left_ankle_roll_link" content_type="model/stl" file="meshes/left_ankle_roll_link.STL"/>
    <mesh name="right_hip_pitch_link" content_type="model/stl" file="meshes/right_hip_pitch_link.STL"/>
    <mesh name="right_hip_roll_link" content_type="model/stl" file="meshes/right_hip_roll_link.STL"/>
    <mesh name="right_hip_yaw_link" content_type="model/stl" file="meshes/right_hip_yaw_link.STL"/>
    <mesh name="right_knee_link" content_type="model/stl" file="meshes/right_knee_link.STL"/>
    <mesh name="right_ankle_pitch_link" content_type="model/stl" file="meshes/right_ankle_pitch_link.STL"/>
    <mesh name="right_ankle_roll_link" content_type="model/stl" file="meshes/right_ankle_roll_link.STL"/>
    <mesh name="waist_roll_link" content_type="model/stl" file="meshes/waist_roll_link.STL"/>
    <mesh name="torso_link" content_type="model/stl" file="meshes/torso_link.STL"/>
    <mesh name="left_shoulder_pitch_link" content_type="model/stl" file="meshes/left_shoulder_pitch_link.STL"/>
    <mesh name="left_shoulder_roll_link" content_type="model/stl" file="meshes/left_shoulder_roll_link.STL"/>
    <mesh name="left_shoulder_yaw_link" content_type="model/stl" file="meshes/left_shoulder_yaw_link.STL"/>
    <mesh name="left_elbow_link" content_type="model/stl" file="meshes/left_elbow_link.STL"/>
    <mesh name="left_wrist_roll_link" content_type="model/stl" file="meshes/left_wrist_roll_link.STL"/>
    <mesh name="left_wrist_pitch_link" content_type="model/stl" file="meshes/left_wrist_pitch_link.STL"/>
    <mesh name="left_wrist_yaw_link" content_type="model/stl" file="meshes/left_wrist_yaw_link.STL"/>
    <mesh name="left_hand_link" content_type="model/stl" file="meshes/left_hand_link.STL"/>
    <mesh name="right_shoulder_pitch_link" content_type="model/stl" file="meshes/right_shoulder_pitch_link.STL"/>
    <mesh name="right_shoulder_roll_link" content_type="model/stl" file="meshes/right_shoulder_roll_link.STL"/>
    <mesh name="right_shoulder_yaw_link" content_type="model/stl" file="meshes/right_shoulder_yaw_link.STL"/>
    <mesh name="right_elbow_link" content_type="model/stl" file="meshes/right_elbow_link.STL"/>
    <mesh name="right_wrist_roll_link" content_type="model/stl" file="meshes/right_wrist_roll_link.STL"/>
    <mesh name="right_wrist_pitch_link" content_type="model/stl" file="meshes/right_wrist_pitch_link.STL"/>
    <mesh name="right_wrist_yaw_link" content_type="model/stl" file="meshes/right_wrist_yaw_link.STL"/>
    <mesh name="right_hand_link" content_type="model/stl" file="meshes/right_hand_link.STL"/>
    <mesh name="Technology head_link" content_type="model/stl" file="meshes/Technology head_link.STL"/>
  </asset>

  <worldbody>
    <geom name="floor" pos="0.001 0 0" size="100 10 .125" type="plane" material="plane" condim="3"
          conaffinity="15" friction="0.6 0.6 0.001"/>
    <light mode="trackcom" pos="0 0 5" dir="0 0 -1"/>
    <body name="pelvis">
      <inertial pos="0.00083229 -3.165e-05 0.084987" quat="0.999992 0.000316471 -0.00264903 -0.00312728" mass="3.189" diaginertia="0.0123657 0.0113015 0.00449499"/>
      <joint name="floating_base_joint" type="free"/>
      <geom type="mesh" contype="0" conaffinity="0" group="1" density="0" rgba="0.75294 0.75294 0.75294 1" mesh="pelvis"/>
      <geom type="mesh" rgba="0.75294 0.75294 0.75294 1" mesh="pelvis"/>
      <body name="left_hip_pitch_link" pos="0 0.0495 0.044">
        <inertial pos="-0.0022605 0.051836 -0.014091" quat="0.599899 0.797342 -0.0646695 0.0135971" mass="0.961" diaginertia="0.00116699 0.000950291 0.000815138"/>
        <joint name="left_hip_pitch_joint" pos="0 0 0" axis="0 1 0" range="-2.3562 2.3562" actuatorfrcrange="-75 75"/>
        <geom type="mesh" contype="0" conaffinity="0" group="1" density="0" rgba="0.75294 0.75294 0.75294 1" mesh="left_hip_pitch_link"/>
        <geom type="mesh" rgba="0.75294 0.75294 0.75294 1" mesh="left_hip_pitch_link"/>
        <body name="left_hip_roll_link" pos="0 0.0555 -0.016">
          <inertial pos="0.0043213 0 -0.027634" quat="0.408553 0.57731 0.577033 0.408449" mass="0.14" diaginertia="0.00018358 0.000141244 0.000101956"/>
          <joint name="left_hip_roll_joint" pos="0 0 0" axis="1 0 0" range="-0.5236 1.5708" actuatorfrcrange="-87 87"/>
          <geom type="mesh" contype="0" conaffinity="0" group="1" density="0" rgba="0.75294 0.75294 0.75294 1" mesh="left_hip_roll_link"/>
          <geom type="mesh" rgba="0.75294 0.75294 0.75294 1" mesh="left_hip_roll_link"/>
          <body name="left_hip_yaw_link" pos="0 0 -0.0536">
            <inertial pos="0.00010121 1.383e-05 -0.102311" quat="0.99999 0.00375205 0.0025479 0.000511966" mass="2.275" diaginertia="0.0191971 0.018658 0.00224713"/>
            <joint name="left_hip_yaw_joint" pos="0 0 0" axis="0 0 1" range="-1.8326 1.8326" actuatorfrcrange="-87 87"/>
            <geom type="mesh" contype="0" conaffinity="0" group="1" density="0" rgba="0.75294 0.75294 0.75294 1" mesh="left_hip_yaw_link"/>
            <geom type="mesh" rgba="0.75294 0.75294 0.75294 1" mesh="left_hip_yaw_link"/>
            <body name="left_knee_link" pos="0 0 -0.3304">
              <inertial pos="0.00334882 -0.00032247 -0.149842" quat="0.698241 -0.0104039 -0.00666549 0.715757" mass="0.635" diaginertia="0.0111018 0.0110139 0.000311373"/>
              <joint name="left_knee_joint" pos="0 0 0" axis="0 1 0" range="-0.01745 2.3562" actuatorfrcrange="-120 120"/>
              <geom type="mesh" contype="0" conaffinity="0" group="1" density="0" rgba="0.75294 0.75294 0.75294 1" mesh="left_knee_link"/>
              <geom type="mesh" rgba="0.75294 0.75294 0.75294 1" mesh="left_knee_link"/>
              <body name="left_ankle_pitch_link" pos="0 0 -0.39">
                <inertial pos="0.0024178 -1.256e-05 -0.0238176" quat="0.704903 0.052882 0.0527757 0.705358" mass="0.22" diaginertia="0.00023561 0.000170507 9.99229e-05"/>
                <joint name="left_ankle_pitch_joint" pos="0 0 0" axis="0 1 0" range="-0.873 1.0472" actuatorfrcrange="-89 89"/>
                <geom type="mesh" contype="0" conaffinity="0" group="1" density="0" rgba="0.75294 0.75294 0.75294 1" mesh="left_ankle_pitch_link"/>
                <geom type="mesh" rgba="0.75294 0.75294 0.75294 1" mesh="left_ankle_pitch_link"/>
                <body name="left_ankle_roll_link" pos="0 0 -0.058">
                  <inertial pos="0.0510876 0.00023922 -0.00447269" quat="0 0.707107 0 0.707107" mass="0.411" diaginertia="0.00047916 0.00047226 9.993e-05"/>
                  <joint name="left_ankle_roll_joint" pos="0 0 0" axis="1 0 0" range="-0.5236 0.5236" actuatorfrcrange="-12 12"/>
                  <geom type="mesh" contype="0" conaffinity="0" group="1" density="0" rgba="0.75294 0.75294 0.75294 1" mesh="left_ankle_roll_link"/>
                  <geom size="0.01 0.1025" pos="0.042 0 -0.019" quat="0.707105 0 0.707108 0" type="capsule" rgba="0.75294 0.75294 0.75294 1"/>
                  <geom size="0.01 0.0925" pos="0.042 0.025 -0.019" quat="0.707105 0 0.707108 0" type="capsule" rgba="0.75294 0.75294 0.75294 1"/>
                  <geom size="0.01 0.0925" pos="0.042 -0.025 -0.019" quat="0.707105 0 0.707108 0" type="capsule" rgba="0.75294 0.75294 0.75294 1"/>
                </body>
              </body>
            </body>
          </body>
        </body>
      </body>
      <body name="right_hip_pitch_link" pos="0 -0.0495 0.044">
        <inertial pos="-0.0022605 -0.051836 -0.014091" quat="0.797342 0.599899 -0.0135971 0.0646695" mass="0.961" diaginertia="0.00116699 0.000950291 0.000815138"/>
        <joint name="right_hip_pitch_joint" pos="0 0 0" axis="0 1 0" range="-2.3562 2.3562" actuatorfrcrange="-75 75"/>
        <geom type="mesh" contype="0" conaffinity="0" group="1" density="0" rgba="0.75294 0.75294 0.75294 1" mesh="right_hip_pitch_link"/>
        <geom type="mesh" rgba="0.75294 0.75294 0.75294 1" mesh="right_hip_pitch_link"/>
        <body name="right_hip_roll_link" pos="0 -0.0555 -0.016">
          <inertial pos="0.0043213 0 -0.027634" quat="0.408553 0.57731 0.577033 0.408449" mass="0.14" diaginertia="0.00018358 0.000141244 0.000101956"/>
          <joint name="right_hip_roll_joint" pos="0 0 0" axis="1 0 0" range="-1.5708 0.5236" actuatorfrcrange="-87 87"/>
          <geom type="mesh" contype="0" conaffinity="0" group="1" density="0" rgba="0.75294 0.75294 0.75294 1" mesh="right_hip_roll_link"/>
          <geom type="mesh" rgba="0.75294 0.75294 0.75294 1" mesh="right_hip_roll_link"/>
          <body name="right_hip_yaw_link" pos="0 0 -0.0536">
            <inertial pos="0.00028095 -0.00037298 -0.102311" quat="0.999997 0.00155532 0.00134116 0.00120674" mass="2.275" diaginertia="0.0191961 0.0186572 0.00224772"/>
            <joint name="right_hip_yaw_joint" pos="0 0 0" axis="0 0 1" range="-1.8326 1.8326" actuatorfrcrange="-87 87"/>
            <geom type="mesh" contype="0" conaffinity="0" group="1" density="0" rgba="0.75294 0.75294 0.75294 1" mesh="right_hip_yaw_link"/>
            <geom type="mesh" rgba="0.75294 0.75294 0.75294 1" mesh="right_hip_yaw_link"/>
            <body name="right_knee_link" pos="0 0 -0.3304">
              <inertial pos="0.0033489 -0.00032248 -0.14984" quat="0.715839 -0.00666391 -0.0104045 0.698156" mass="0.635" diaginertia="0.0111013 0.0110142 0.000311373"/>
              <joint name="right_knee_joint" pos="0 0 0" axis="0 1 0" range="-0.01745 2.3562" actuatorfrcrange="-120 120"/>
              <geom type="mesh" contype="0" conaffinity="0" group="1" density="0" rgba="0.75294 0.75294 0.75294 1" mesh="right_knee_link"/>
              <geom type="mesh" rgba="0.75294 0.75294 0.75294 1" mesh="right_knee_link"/>
              <body name="right_ankle_pitch_link" pos="0 0 -0.39">
                <inertial pos="0.0024178 -1.257e-05 -0.023818" quat="0.704903 0.052882 0.0527757 0.705358" mass="0.22" diaginertia="0.00023561 0.000170507 9.99229e-05"/>
                <joint name="right_ankle_pitch_joint" pos="0 0 0" axis="0 1 0" range="-0.873 1.0472" actuatorfrcrange="-89 89"/>
                <geom type="mesh" contype="0" conaffinity="0" group="1" density="0" rgba="0.75294 0.75294 0.75294 1" mesh="right_ankle_pitch_link"/>
                <geom type="mesh" rgba="0.75294 0.75294 0.75294 1" mesh="right_ankle_pitch_link"/>
                <body name="right_ankle_roll_link" pos="0 0 -0.058">
                  <inertial pos="0.0510876 0.00023921 -0.00447269" quat="0 0.707107 0 0.707107" mass="0.411" diaginertia="0.00047916 0.00047226 9.993e-05"/>
                  <joint name="right_ankle_roll_joint" pos="0 0 0" axis="1 0 0" range="-0.5236 0.5236" actuatorfrcrange="-12 12"/>
                  <geom type="mesh" contype="0" conaffinity="0" group="1" density="0" rgba="0.75294 0.75294 0.75294 1" mesh="right_ankle_roll_link"/>
                  <geom size="0.01 0.1025" pos="0.042 0 -0.019" quat="0.707105 0 0.707108 0" type="capsule" rgba="0.75294 0.75294 0.75294 1"/>
                  <geom size="0.01 0.0925" pos="0.042 0.025 -0.019" quat="0.707105 0 0.707108 0" type="capsule" rgba="0.75294 0.75294 0.75294 1"/>
                  <geom size="0.01 0.0925" pos="0.042 -0.025 -0.019" quat="0.707105 0 0.707108 0" type="capsule" rgba="0.75294 0.75294 0.75294 1"/>
                </body>
              </body>
            </body>
          </body>
        </body>
      </body>
      <body name="waist_roll_link" pos="0.00085 0 0.19">
        <inertial pos="-0.00017849 0 0.00743447" quat="0.514981 0.484556 0.484556 0.514981" mass="0.259" diaginertia="0.00011059 0.000104495 8.4235e-05"/>
        <joint name="waist_roll_joint" pos="0 0 0" axis="1 0 0" range="-0.5236 0.5236" actuatorfrcrange="-87 87"/>
        <geom type="mesh" contype="0" conaffinity="0" group="1" density="0" rgba="0.75294 0.75294 0.75294 1" mesh="waist_roll_link"/>
        <body name="torso_link">
          <inertial pos="-0.00124613 -0.00517123 0.261664" quat="0.999607 0.0236839 0.0143157 -0.0045496" mass="6.886" diaginertia="0.134104 0.130091 0.0208243"/>
          <joint name="waist_yaw_joint" pos="0 0 0" axis="0 0 1" range="-1.5708 1.5708" actuatorfrcrange="-87 87"/>
          <geom type="mesh" contype="0" conaffinity="0" group="1" density="0" rgba="0.75294 0.75294 0.75294 1" mesh="torso_link"/>
          <geom type="mesh" rgba="0.75294 0.75294 0.75294 1" mesh="torso_link"/>
          <geom pos="-0.012 0 0.348" quat="1 0 0 0" type="mesh" contype="0" conaffinity="0" group="1" density="0" rgba="1 1 1 1" mesh="Technology head_link"/>
          <geom pos="-0.012 0 0.348" quat="1 0 0 0" type="mesh" rgba="1 1 1 1" mesh="Technology head_link"/>
          <body name="left_shoulder_pitch_link" pos="-0.015 0.05835 0.2885">
            <inertial pos="5.543e-05 0.0554533 5.429e-05" quat="0.500477 0.499362 -0.499832 0.500328" mass="1.277" diaginertia="0.00194002 0.00178135 0.00103975"/>
            <joint name="left_shoulder_pitch_joint" pos="0 0 0" axis="0 1 0" range="-3.6652 2.0944" actuatorfrcrange="-48 48"/>
            <geom type="mesh" contype="0" conaffinity="0" group="1" density="0" rgba="0.75294 0.75294 0.75294 1" mesh="left_shoulder_pitch_link"/>
            <geom type="mesh" rgba="0.75294 0.75294 0.75294 1" mesh="left_shoulder_pitch_link"/>
            <body name="left_shoulder_roll_link" pos="-5e-05 0.1012 0">
              <inertial pos="0 -0.00015563 -0.00797243" quat="0.449914 0.545507 0.449914 0.545507" mass="0.229" diaginertia="7.05648e-05 6.60152e-05 5.784e-05"/>
              <joint name="left_shoulder_roll_joint" pos="0 0 0" axis="1 0 0" range="-0.2618 3.1416" actuatorfrcrange="-84 84"/>
              <geom type="mesh" contype="0" conaffinity="0" group="1" density="0" rgba="0.75294 0.75294 0.75294 1" mesh="left_shoulder_roll_link"/>
              <geom type="mesh" rgba="0.75294 0.75294 0.75294 1" mesh="left_shoulder_roll_link"/>
              <body name="left_shoulder_yaw_link">
                <inertial pos="-7.8318e-05 0.001011 -0.12915" mass="1.194" diaginertia="0.00412845 0.00411827 0.00084103"/>
                <joint name="left_shoulder_yaw_joint" pos="0 0 0" axis="0 0 1" range="-2.1817 2.1817" actuatorfrcrange="-84 84"/>
                <geom type="mesh" contype="0" conaffinity="0" group="1" density="0" rgba="0.75294 0.75294 0.75294 1" mesh="left_shoulder_yaw_link"/>
                <geom type="mesh" rgba="0.75294 0.75294 0.75294 1" mesh="left_shoulder_yaw_link"/>
                <body name="left_elbow_link" pos="0 0 -0.23">
                  <inertial pos="0.0167741 0 -0.00133301" quat="0 0.684589 0 0.728929" mass="0.185" diaginertia="0.000124726 0.00011358 7.98035e-05"/>
                  <joint name="left_elbow_joint" pos="0 0 0" axis="0 1 0" range="-0.6981 1.5707" actuatorfrcrange="-37 37"/>
                  <geom type="mesh" contype="0" conaffinity="0" group="1" density="0" rgba="0.75294 0.75294 0.75294 1" mesh="left_elbow_link"/>
                  <geom type="mesh" rgba="0.75294 0.75294 0.75294 1" mesh="left_elbow_link"/>
                  <body name="left_wrist_roll_link">
                    <inertial pos="0.0985386 -0.00025438 -0.00071846" quat="0.49661 0.497949 0.510134 0.495166" mass="1.372" diaginertia="0.00443163 0.00434654 0.000486748"/>
                    <joint name="left_wrist_roll_joint" pos="0 0 0" axis="1 0 0" range="-2.0071 2.0071" actuatorfrcrange="-37 37"/>
                    <geom type="mesh" contype="0" conaffinity="0" group="1" density="0" rgba="0.75294 0.75294 0.75294 1" mesh="left_wrist_roll_link"/>
                    <geom type="mesh" rgba="0.75294 0.75294 0.75294 1" mesh="left_wrist_roll_link"/>
                    <body name="left_wrist_pitch_link" pos="0.235 0 0">
                      <inertial pos="0.0075268 0 0" quat="0.5 0.5 -0.5 0.5" mass="0.042" diaginertia="1.443e-05 1.052e-05 7.83e-06"/>
                      <joint name="left_wrist_pitch_joint" pos="0 0 0" axis="0 1 0" range="-0.5236 0.5236" actuatorfrcrange="-20 20"/>
                      <geom type="mesh" contype="0" conaffinity="0" group="1" density="0" rgba="0.75294 0.75294 0.75294 1" mesh="left_wrist_pitch_link"/>
                      <geom type="mesh" rgba="0.75294 0.75294 0.75294 1" mesh="left_wrist_pitch_link"/>
                      <body name="left_wrist_yaw_link" pos="0.021 0 0">
                        <inertial pos="0.065664 0.0134012 -0.00553818" quat="0.63389 0.310977 0.60498 0.368071" mass="0.53" diaginertia="0.00175271 0.00146535 0.000533341"/>
                        <joint name="left_wrist_yaw_joint" pos="0 0 0" axis="0 0 1" range="-1.1344 1.1344" actuatorfrcrange="-25 25"/>
                        <geom type="mesh" contype="0" conaffinity="0" group="1" density="0" rgba="0.75294 0.75294 0.75294 1" mesh="left_wrist_yaw_link"/>
                        <geom pos="0.031 0 0" quat="1 0 0 0" type="mesh" contype="0" conaffinity="0" group="1" density="0" rgba="1 1 1 1" mesh="left_hand_link"/>
                        <geom pos="0.031 0 0" quat="1 0 0 0" type="mesh" rgba="1 1 1 1" mesh="left_hand_link"/>
                      </body>
                    </body>
                  </body>
                </body>
              </body>
            </body>
          </body>
          <body name="right_shoulder_pitch_link" pos="-0.015 -0.0583 0.2885">
            <inertial pos="0.00015543 -0.0554533 -5.429e-05" quat="0.500328 0.499832 -0.499362 0.500477" mass="1.277" diaginertia="0.00194002 0.00178135 0.00103975"/>
            <joint name="right_shoulder_pitch_joint" pos="0 0 0" axis="0 1 0" range="-3.6652 2.0944" actuatorfrcrange="-48 48"/>
            <geom type="mesh" contype="0" conaffinity="0" group="1" density="0" rgba="0.75294 0.75294 0.75294 1" mesh="right_shoulder_pitch_link"/>
            <geom type="mesh" rgba="0.75294 0.75294 0.75294 1" mesh="right_shoulder_pitch_link"/>
            <body name="right_shoulder_roll_link" pos="5e-05 -0.1012 0">
              <inertial pos="0 -0.00015563 -0.00797243" quat="0.449914 0.545507 0.449914 0.545507" mass="0.229" diaginertia="7.05648e-05 6.60152e-05 5.784e-05"/>
              <joint name="right_shoulder_roll_joint" pos="0 0 0" axis="1 0 0" range="-3.1416 0.2618" actuatorfrcrange="-84 84"/>
              <geom type="mesh" contype="0" conaffinity="0" group="1" density="0" rgba="0.75294 0.75294 0.75294 1" mesh="right_shoulder_roll_link"/>
              <geom type="mesh" rgba="0.75294 0.75294 0.75294 1" mesh="right_shoulder_roll_link"/>
              <body name="right_shoulder_yaw_link">
                <inertial pos="-7.8318e-05 0.001011 -0.12915" mass="1.194" diaginertia="0.00412845 0.00411827 0.00084103"/>
                <joint name="right_shoulder_yaw_joint" pos="0 0 0" axis="0 0 1" range="-2.1817 2.1817" actuatorfrcrange="-84 84"/>
                <geom type="mesh" contype="0" conaffinity="0" group="1" density="0" rgba="0.75294 0.75294 0.75294 1" mesh="right_shoulder_yaw_link"/>
                <geom type="mesh" rgba="0.75294 0.75294 0.75294 1" mesh="right_shoulder_yaw_link"/>
                <body name="right_elbow_link" pos="0 0 -0.23">
                  <inertial pos="0.0167741 0 -0.00133301" quat="0 0.684589 0 0.728929" mass="0.185" diaginertia="0.000124726 0.00011358 7.98035e-05"/>
                  <joint name="right_elbow_joint" pos="0 0 0" axis="0 1 0" range="-0.6981 1.5707" actuatorfrcrange="-37 37"/>
                  <geom type="mesh" contype="0" conaffinity="0" group="1" density="0" rgba="0.75294 0.75294 0.75294 1" mesh="right_elbow_link"/>
                  <geom type="mesh" rgba="0.75294 0.75294 0.75294 1" mesh="right_elbow_link"/>
                  <body name="right_wrist_roll_link">
                    <inertial pos="0.0985386 -0.00025438 -0.00071846" quat="0.49661 0.497949 0.510134 0.495166" mass="1.372" diaginertia="0.00443163 0.00434654 0.000486748"/>
                    <joint name="right_wrist_roll_joint" pos="0 0 0" axis="1 0 0" range="-2.0071 2.0071" actuatorfrcrange="-37 37"/>
                    <geom type="mesh" contype="0" conaffinity="0" group="1" density="0" rgba="0.75294 0.75294 0.75294 1" mesh="right_wrist_roll_link"/>
                    <geom type="mesh" rgba="0.75294 0.75294 0.75294 1" mesh="right_wrist_roll_link"/>
                    <body name="right_wrist_pitch_link" pos="0.235 0 0">
                      <inertial pos="0.0075268 0 0" quat="0.5 0.5 -0.5 0.5" mass="0.042" diaginertia="1.443e-05 1.052e-05 7.83e-06"/>
                      <joint name="right_wrist_pitch_joint" pos="0 0 0" axis="0 1 0" range="-0.5236 0.5236" actuatorfrcrange="-20 20"/>
                      <geom type="mesh" contype="0" conaffinity="0" group="1" density="0" rgba="0.75294 0.75294 0.75294 1" mesh="right_wrist_pitch_link"/>
                      <geom type="mesh" rgba="0.75294 0.75294 0.75294 1" mesh="right_wrist_pitch_link"/>
                      <body name="right_wrist_yaw_link" pos="0.021 0 0">
                        <inertial pos="0.0587513 0.0259836 0.0207622" quat="0.303167 0.500411 0.353966 0.729649" mass="0.53" diaginertia="0.00176432 0.00150236 0.000557811"/>
                        <joint name="right_wrist_yaw_joint" pos="0 0 0" axis="0 0 1" range="-1.1344 1.1344" actuatorfrcrange="-25 25"/>
                        <geom type="mesh" contype="0" conaffinity="0" group="1" density="0" rgba="0.75294 0.75294 0.75294 1" mesh="right_wrist_yaw_link"/>
                        <geom pos="0.031 0 0" quat="1 0 0 0" type="mesh" contype="0" conaffinity="0" group="1" density="0" rgba="1 1 1 1" mesh="right_hand_link"/>
                        <geom pos="0.031 0 0" quat="1 0 0 0" type="mesh" rgba="1 1 1 1" mesh="right_hand_link"/>
                      </body>
                    </body>
                  </body>
                </body>
              </body>
            </body>
          </body>
        </body>
      </body>
    </body>
  </worldbody>
  
  <actuator>
    <motor name="left_hip_pitch_joint" joint="left_hip_pitch_joint"/>
    <motor name="left_hip_roll_joint" joint="left_hip_roll_joint"/>
    <motor name="left_hip_yaw_joint" joint="left_hip_yaw_joint"/>
    <motor name="left_knee_joint" joint="left_knee_joint"/>
    <motor name="left_ankle_pitch_joint" joint="left_ankle_pitch_joint"/>
    <motor name="left_ankle_roll_joint" joint="left_ankle_roll_joint"/>
    <motor name="right_hip_pitch_joint" joint="right_hip_pitch_joint"/>
    <motor name="right_hip_roll_joint" joint="right_hip_roll_joint"/>
    <motor name="right_hip_yaw_joint" joint="right_hip_yaw_joint"/>
    <motor name="right_knee_joint" joint="right_knee_joint"/>
    <motor name="right_ankle_pitch_joint" joint="right_ankle_pitch_joint"/>
    <motor name="right_ankle_roll_joint" joint="right_ankle_roll_joint"/>
    <motor name="waist_roll_joint" joint="waist_roll_joint"/>
    <motor name="waist_yaw_joint" joint="waist_yaw_joint"/>
    <motor name="left_shoulder_pitch_joint" joint="left_shoulder_pitch_joint"/>
    <motor name="left_shoulder_roll_joint" joint="left_shoulder_roll_joint"/>
    <motor name="left_shoulder_yaw_joint" joint="left_shoulder_yaw_joint"/>
    <motor name="left_elbow_joint" joint="left_elbow_joint"/>
    <motor name="left_wrist_roll_joint" joint="left_wrist_roll_joint"/>
    <motor name="left_wrist_pitch_joint" joint="left_wrist_pitch_joint"/>
    <motor name="left_wrist_yaw_joint" joint="left_wrist_yaw_joint"/>
    <motor name="right_shoulder_pitch_joint" joint="right_shoulder_pitch_joint"/>
    <motor name="right_shoulder_roll_joint" joint="right_shoulder_roll_joint"/>
    <motor name="right_shoulder_yaw_joint" joint="right_shoulder_yaw_joint"/>
    <motor name="right_elbow_joint" joint="right_elbow_joint"/>
    <motor name="right_wrist_roll_joint" joint="right_wrist_roll_joint"/>
    <motor name="right_wrist_pitch_joint" joint="right_wrist_pitch_joint"/>
    <motor name="right_wrist_yaw_joint" joint="right_wrist_yaw_joint"/>
  </actuator>

</mujoco>
