<mujoco model="F1">
  <compiler angle="radian" meshdir="./meshes/"/>

  <asset>
    <mesh name="pelvis_v3" file="pelvis_v3.STL"/>
    <mesh name="left_hip_pitch_link_v2" file="left_hip_pitch_link_v2.STL"/>
    <mesh name="left_hip_roll_link" file="left_hip_roll_link.STL"/>
    <mesh name="left_hip_yaw_link" file="left_hip_yaw_link.STL"/>
    <mesh name="left_knee_link" file="left_knee_link.STL"/>
    <mesh name="left_ankle_pitch_link" file="left_ankle_pitch_link.STL"/>
    <mesh name="left_ankle_roll_link_v2" file="left_ankle_roll_link_v2.STL"/>
    <mesh name="right_hip_pitch_link_v2" file="right_hip_pitch_link_v2.STL"/>
    <mesh name="right_hip_roll_link" file="right_hip_roll_link.STL"/>
    <mesh name="right_hip_yaw_link" file="right_hip_yaw_link.STL"/>
    <mesh name="right_knee_link" file="right_knee_link.STL"/>
    <mesh name="right_ankle_pitch_link" file="right_ankle_pitch_link.STL"/>
    <mesh name="right_ankle_roll_link_v2" file="right_ankle_roll_link_v2.STL"/>
    <mesh name="waist_yaw_link_v2" file="waist_yaw_link_v2.STL"/>
    <mesh name="waist_roll_link_v3" file="waist_roll_link_v3.STL"/>
    <mesh name="torso_link_v2_1" file="torso_link_v2_1.STL"/>
    <mesh name="left_shoulder_pitch_link" file="left_shoulder_pitch_link.STL"/>
    <mesh name="left_shoulder_roll_link" file="left_shoulder_roll_link.STL"/>
    <mesh name="left_shoulder_yaw_link" file="left_shoulder_yaw_link.STL"/>
    <mesh name="left_elbow_link" file="left_elbow_link.STL"/>
    <mesh name="left_wrist_roll_link" file="left_wrist_roll_link.STL"/>
    <mesh name="left_wrist_pitch_link" file="left_wrist_pitch_link.STL"/>
    <mesh name="left_wrist_yaw_link" file="left_wrist_yaw_link.STL"/>
    <mesh name="left_hand_link" file="left_hand_link.STL"/>
    <mesh name="right_shoulder_pitch_link" file="right_shoulder_pitch_link.STL"/>
    <mesh name="right_shoulder_roll_link" file="right_shoulder_roll_link.STL"/>
    <mesh name="right_shoulder_yaw_link" file="right_shoulder_yaw_link.STL"/>
    <mesh name="right_elbow_link" file="right_elbow_link.STL"/>
    <mesh name="right_wrist_roll_link" file="right_wrist_roll_link.STL"/>
    <mesh name="right_wrist_pitch_link" file="right_wrist_pitch_link.STL"/>
    <mesh name="right_wrist_yaw_link" file="right_wrist_yaw_link.STL"/>
    <mesh name="right_hand_link" file="right_hand_link.STL"/>
    <mesh name="head_yaw_link" file="head_yaw_link.STL"/>
    <mesh name="head_pitch_link" file="head_pitch_link.STL"/>
  </asset>

  <worldbody>
    <body name="pelvis" pos="0 0 0.872">
      <inertial pos="1.227e-05 0 0.00175202" quat="0.707113 0.707071 -0.00603929 0.00224665" mass="1.923" diaginertia="0.00328643 0.00327877 0.00187875"/>
      <joint name="floating_base_joint" type="free" limited="false" actuatorfrclimited="false"/>
      <geom type="mesh" contype="0" conaffinity="0" group="1" density="0" rgba="0.75294 0.75294 0.75294 1" mesh="pelvis_v3"/>
      <geom type="mesh" rgba="0.75294 0.75294 0.75294 1" mesh="pelvis_v3"/>
      <body name="left_hip_pitch_link" pos="0 0.0495 0">
        <inertial pos="-0.00059823 0.053979 -0.0042224" quat="0.652315 0.75755 -0.0242065 0.00423816" mass="1.04" diaginertia="0.00138575 0.00113626 0.000872142"/>
        <joint name="left_hip_pitch_joint" pos="0 0 0" axis="0 1 0" range="-2.3562 2.3562" actuatorfrcrange="-75 75"/>
        <geom type="mesh" contype="0" conaffinity="0" group="1" density="0" rgba="0.75294 0.75294 0.75294 1" mesh="left_hip_pitch_link_v2"/>
        <geom type="mesh" rgba="0.75294 0.75294 0.75294 1" mesh="left_hip_pitch_link_v2"/>
        <body name="left_hip_roll_link" pos="0 0.0555 -0.005">
          <inertial pos="0.0043213 0 -0.027634" quat="0.408553 0.57731 0.577033 0.408449" mass="0.14" diaginertia="0.00018358 0.000141244 0.000101956"/>
          <joint name="left_hip_roll_joint" pos="0 0 0" axis="1 0 0" range="-0.5236 1.5708" actuatorfrcrange="-87 87"/>
          <geom type="mesh" contype="0" conaffinity="0" group="1" density="0" rgba="0.75294 0.75294 0.75294 1" mesh="left_hip_roll_link"/>
          <geom type="mesh" rgba="0.75294 0.75294 0.75294 1" mesh="left_hip_roll_link"/>
          <body name="left_hip_yaw_link" pos="0 0 -0.0536">
            <inertial pos="0.00010121 1.383e-05 -0.102311" quat="0.99999 0.00375205 0.0025479 0.000511966" mass="2.275" diaginertia="0.0191971 0.018658 0.00224713"/>
            <joint name="left_hip_yaw_joint" pos="0 0 0" axis="0 0 1" range="-1.8326 1.8326" actuatorfrcrange="-87 87"/>
            <geom type="mesh" contype="0" conaffinity="0" group="1" density="0" rgba="0.75294 0.75294 0.75294 1" mesh="left_hip_yaw_link"/>
            <geom type="mesh" rgba="0.75294 0.75294 0.75294 1" mesh="left_hip_yaw_link"/>
            <body name="left_knee_link" pos="0 0 -0.3304">
              <inertial pos="0.00334882 -0.00032247 -0.149842" quat="0.698241 -0.0104039 -0.00666549 0.715757" mass="0.635" diaginertia="0.0111018 0.0110139 0.000311373"/>
              <joint name="left_knee_joint" pos="0 0 0" axis="0 1 0" range="-0.01745 2.3562" actuatorfrcrange="-120 120"/>
              <geom type="mesh" contype="0" conaffinity="0" group="1" density="0" rgba="0.75294 0.75294 0.75294 1" mesh="left_knee_link"/>
              <geom type="mesh" rgba="0.75294 0.75294 0.75294 1" mesh="left_knee_link"/>
              <body name="left_ankle_pitch_link" pos="0 0 -0.39">
                <inertial pos="0.0024178 -1.256e-05 -0.0238176" quat="0.704903 0.052882 0.0527757 0.705358" mass="0.22" diaginertia="0.00023561 0.000170507 9.99229e-05"/>
                <joint name="left_ankle_pitch_joint" pos="0 0 0" axis="0 1 0" range="-0.873 1.0472" actuatorfrcrange="-89 89"/>
                <geom type="mesh" contype="0" conaffinity="0" group="1" density="0" rgba="0.75294 0.75294 0.75294 1" mesh="left_ankle_pitch_link"/>
                <geom type="mesh" rgba="0.75294 0.75294 0.75294 1" mesh="left_ankle_pitch_link"/>
                <body name="left_ankle_roll_link" pos="0 0 -0.058">
                  <inertial pos="0.0510876 0.00023922 -0.00447269" quat="0 0.707107 0 0.707107" mass="0.411" diaginertia="0.00047916 0.00047226 9.993e-05"/>
                  <joint name="left_ankle_roll_joint" pos="0 0 0" axis="1 0 0" range="-0.5236 0.5236" actuatorfrcrange="-12 12"/>
                  <geom type="mesh" contype="0" conaffinity="0" group="1" density="0" rgba="0.75294 0.75294 0.75294 1" mesh="left_ankle_roll_link_v2"/>
                  <geom size="0.105 0.033 0.01" pos="0.04 0 -0.013" type="box" rgba="0.75294 0.75294 0.75294 1"/>
                </body>
              </body>
            </body>
          </body>
        </body>
      </body>
      <body name="right_hip_pitch_link" pos="0 -0.0495 0">
        <inertial pos="-0.00059823 -0.053979 -0.0042224" quat="0.75755 0.652315 -0.00423816 0.0242065" mass="1.04" diaginertia="0.00138575 0.00113626 0.000872142"/>
        <joint name="right_hip_pitch_joint" pos="0 0 0" axis="0 1 0" range="-2.3562 2.3562" actuatorfrcrange="-75 75"/>
        <geom type="mesh" contype="0" conaffinity="0" group="1" density="0" rgba="0.75294 0.75294 0.75294 1" mesh="right_hip_pitch_link_v2"/>
        <geom type="mesh" rgba="0.75294 0.75294 0.75294 1" mesh="right_hip_pitch_link_v2"/>
        <body name="right_hip_roll_link" pos="0 -0.0555 -0.005">
          <inertial pos="0.0043213 0 -0.027634" quat="0.408553 0.57731 0.577033 0.408449" mass="0.14" diaginertia="0.00018358 0.000141244 0.000101956"/>
          <joint name="right_hip_roll_joint" pos="0 0 0" axis="1 0 0" range="-1.5708 0.5236" actuatorfrcrange="-87 87"/>
          <geom type="mesh" contype="0" conaffinity="0" group="1" density="0" rgba="0.75294 0.75294 0.75294 1" mesh="right_hip_roll_link"/>
          <geom type="mesh" rgba="0.75294 0.75294 0.75294 1" mesh="right_hip_roll_link"/>
          <body name="right_hip_yaw_link" pos="0 0 -0.0536">
            <inertial pos="0.00028095 -0.00037298 -0.102311" quat="0.999997 0.00155532 0.00134116 0.00120674" mass="2.275" diaginertia="0.0191961 0.0186572 0.00224772"/>
            <joint name="right_hip_yaw_joint" pos="0 0 0" axis="0 0 1" range="-1.8326 1.8326" actuatorfrcrange="-87 87"/>
            <geom type="mesh" contype="0" conaffinity="0" group="1" density="0" rgba="0.75294 0.75294 0.75294 1" mesh="right_hip_yaw_link"/>
            <geom type="mesh" rgba="0.75294 0.75294 0.75294 1" mesh="right_hip_yaw_link"/>
            <body name="right_knee_link" pos="0 0 -0.3304">
              <inertial pos="0.0033489 -0.00032248 -0.14984" quat="0.715839 -0.00666391 -0.0104045 0.698156" mass="0.635" diaginertia="0.0111013 0.0110142 0.000311373"/>
              <joint name="right_knee_joint" pos="0 0 0" axis="0 1 0" range="-0.01745 2.3562" actuatorfrcrange="-120 120"/>
              <geom type="mesh" contype="0" conaffinity="0" group="1" density="0" rgba="0.75294 0.75294 0.75294 1" mesh="right_knee_link"/>
              <geom type="mesh" rgba="0.75294 0.75294 0.75294 1" mesh="right_knee_link"/>
              <body name="right_ankle_pitch_link" pos="0 0 -0.39">
                <inertial pos="0.0024178 -1.257e-05 -0.023818" quat="0.704903 0.052882 0.0527757 0.705358" mass="0.22" diaginertia="0.00023561 0.000170507 9.99229e-05"/>
                <joint name="right_ankle_pitch_joint" pos="0 0 0" axis="0 1 0" range="-0.873 1.0472" actuatorfrcrange="-89 89"/>
                <geom type="mesh" contype="0" conaffinity="0" group="1" density="0" rgba="0.75294 0.75294 0.75294 1" mesh="right_ankle_pitch_link"/>
                <geom type="mesh" rgba="0.75294 0.75294 0.75294 1" mesh="right_ankle_pitch_link"/>
                <body name="right_ankle_roll_link" pos="0 0 -0.058">
                  <inertial pos="0.0510876 0.00023921 -0.00447269" quat="0 0.707107 0 0.707107" mass="0.411" diaginertia="0.00047916 0.00047226 9.993e-05"/>
                  <joint name="right_ankle_roll_joint" pos="0 0 0" axis="1 0 0" range="-0.5236 0.5236" actuatorfrcrange="-12 12"/>
                  <geom type="mesh" contype="0" conaffinity="0" group="1" density="0" rgba="0.75294 0.75294 0.75294 1" mesh="right_ankle_roll_link_v2"/>
                  <geom size="0.105 0.033 0.01" pos="0.04 0 -0.013" type="box" rgba="0.75294 0.75294 0.75294 1"/>
                </body>
              </body>
            </body>
          </body>
        </body>
      </body>
      <body name="waist_yaw_link" pos="0 0 0.0925">
        <inertial pos="-0.000168719 0 0.00494718" quat="0.705214 0.0517024 0.0517024 0.705214" mass="0.274" diaginertia="0.000141864 0.000115748 0.00010802"/>
        <joint name="waist_yaw_joint" pos="0 0 0" axis="0 0 1" range="-1.5708 1.5708" actuatorfrcrange="-87 87"/>
        <geom type="mesh" contype="0" conaffinity="0" group="1" density="0" rgba="1 1 1 1" mesh="waist_yaw_link_v2"/>
        <geom type="mesh" contype="0" conaffinity="0" group="1" density="0" rgba="0.75294 0.75294 0.75294 1" mesh="waist_roll_link_v3"/>
        <geom type="mesh" rgba="0.75294 0.75294 0.75294 1" mesh="waist_roll_link_v3"/>
        <body name="torso_link">
          <inertial pos="-0.00476833 7.216e-05 0.205038" quat="0.999772 -0.000101648 0.0213459 0.00109103" mass="7.06" diaginertia="0.159722 0.154759 0.0191061"/>
          <joint name="waist_roll_joint" pos="0 0 0" axis="1 0 0" range="-0.5236 0.5236" actuatorfrcrange="-87 87"/>
          <geom type="mesh" contype="0" conaffinity="0" group="1" density="0" rgba="0.75294 0.75294 0.75294 1" mesh="torso_link_v2_1"/>
          <geom type="mesh" rgba="0.75294 0.75294 0.75294 1" mesh="torso_link_v2_1"/>
          <body name="left_shoulder_pitch_link" pos="-0.015 0.0563 0.342" euler="0 0.2 0">
            <inertial pos="5.543e-05 0.0554533 5.429e-05" quat="0.500477 0.499362 -0.499832 0.500328" mass="1.277" diaginertia="0.00194002 0.00178135 0.00103975"/>
<!--            <joint name="left_shoulder_pitch_joint" pos="0 0 0" axis="0 1 0" range="-3.6652 2.0944" actuatorfrcrange="-48 48"/>-->
            <geom type="mesh" contype="0" conaffinity="0" group="1" density="0" rgba="0.75294 0.75294 0.75294 1" mesh="left_shoulder_pitch_link"/>
            <geom type="mesh" rgba="0.75294 0.75294 0.75294 1" mesh="left_shoulder_pitch_link"/>
            <body name="left_shoulder_roll_link" pos="-5e-05 0.1012 0" euler="0.2 0 0">
              <inertial pos="0 -0.00015563 -0.00797243" quat="0.449914 0.545507 0.449914 0.545507" mass="0.229" diaginertia="7.05648e-05 6.60152e-05 5.784e-05"/>
<!--              <joint name="left_shoulder_roll_joint" pos="0 0 0" axis="1 0 0" range="-0.2618 3.1416" actuatorfrcrange="-84 84"/>-->
              <geom type="mesh" contype="0" conaffinity="0" group="1" density="0" rgba="0.75294 0.75294 0.75294 1" mesh="left_shoulder_roll_link"/>
              <geom type="mesh" rgba="0.75294 0.75294 0.75294 1" mesh="left_shoulder_roll_link"/>
              <body name="left_shoulder_yaw_link">
                <inertial pos="-7.8318e-05 0.001011 -0.12915" mass="1.194" diaginertia="0.00412845 0.00411827 0.00084103"/>
<!--                <joint name="left_shoulder_yaw_joint" pos="0 0 0" axis="0 0 1" range="-2.1817 2.1817" actuatorfrcrange="-84 84"/>-->
                <geom type="mesh" contype="0" conaffinity="0" group="1" density="0" rgba="0.75294 0.75294 0.75294 1" mesh="left_shoulder_yaw_link"/>
                <geom type="mesh" rgba="0.75294 0.75294 0.75294 1" mesh="left_shoulder_yaw_link"/>
                <body name="left_elbow_link" pos="0 0 -0.23" euler="0 1.0 0">
                  <inertial pos="0.0167741 0 -0.00133301" quat="0 0.684589 0 0.728929" mass="0.185" diaginertia="0.000124726 0.00011358 7.98035e-05"/>
<!--                  <joint name="left_elbow_joint" pos="0 0 0" axis="0 1 0" range="-0.6981 1.5707" actuatorfrcrange="-37 37"/>-->
                  <geom type="mesh" contype="0" conaffinity="0" group="1" density="0" rgba="0.75294 0.75294 0.75294 1" mesh="left_elbow_link"/>
                  <geom type="mesh" rgba="0.75294 0.75294 0.75294 1" mesh="left_elbow_link"/>
                  <body name="left_wrist_roll_link">
                    <inertial pos="0.0985386 -0.00025438 -0.00071846" quat="0.49661 0.497949 0.510134 0.495166" mass="1.372" diaginertia="0.00443163 0.00434654 0.000486748"/>
<!--                    <joint name="left_wrist_roll_joint" pos="0 0 0" axis="1 0 0" range="-2.0071 2.0071" actuatorfrcrange="-37 37"/>-->
                    <geom type="mesh" contype="0" conaffinity="0" group="1" density="0" rgba="0.75294 0.75294 0.75294 1" mesh="left_wrist_roll_link"/>
                    <geom type="mesh" rgba="0.75294 0.75294 0.75294 1" mesh="left_wrist_roll_link"/>
                    <body name="left_wrist_pitch_link" pos="0.235 0 0">
                      <inertial pos="0.0075268 0 0" quat="0.5 0.5 -0.5 0.5" mass="0.042" diaginertia="1.443e-05 1.052e-05 7.83e-06"/>
<!--                      <joint name="left_wrist_pitch_joint" pos="0 0 0" axis="0 1 0" range="-0.5236 0.5236" actuatorfrcrange="-20 20"/>-->
                      <geom type="mesh" contype="0" conaffinity="0" group="1" density="0" rgba="0.75294 0.75294 0.75294 1" mesh="left_wrist_pitch_link"/>
                      <geom type="mesh" rgba="0.75294 0.75294 0.75294 1" mesh="left_wrist_pitch_link"/>
                      <body name="left_wrist_yaw_link" pos="0.021 0 0">
                        <inertial pos="0.086187 -0.00635348 0.00761055" quat="0.673531 0.336171 0.566101 0.335968" mass="0.53" diaginertia="0.00218929 0.00185367 0.000486625"/>
<!--                        <joint name="left_wrist_yaw_joint" pos="0 0 0" axis="0 0 1" range="-1.1344 1.1344" actuatorfrcrange="-25 25"/>-->
                        <geom type="mesh" contype="0" conaffinity="0" group="1" density="0" rgba="0.75294 0.75294 0.75294 1" mesh="left_wrist_yaw_link"/>
                        <geom pos="0.031 0 0" quat="1 0 0 0" type="mesh" contype="0" conaffinity="0" group="1" density="0" rgba="0.75294 0.75294 0.75294 1" mesh="left_hand_link"/>
                        <geom pos="0.031 0 0" quat="1 0 0 0" type="mesh" rgba="0.75294 0.75294 0.75294 1" mesh="left_hand_link"/>
                      </body>
                    </body>
                  </body>
                </body>
              </body>
            </body>
          </body>
          <body name="right_shoulder_pitch_link" pos="-0.015 -0.0563 0.342" euler="0 0.2 0">
            <inertial pos="0.00015543 -0.0554533 -5.429e-05" quat="0.500328 0.499832 -0.499362 0.500477" mass="1.277" diaginertia="0.00194002 0.00178135 0.00103975"/>
<!--            <joint name="right_shoulder_pitch_joint" pos="0 0 0" axis="0 1 0" range="-3.6652 2.0944" actuatorfrcrange="-48 48"/>-->
            <geom type="mesh" contype="0" conaffinity="0" group="1" density="0" rgba="0.75294 0.75294 0.75294 1" mesh="right_shoulder_pitch_link"/>
            <geom type="mesh" rgba="0.75294 0.75294 0.75294 1" mesh="right_shoulder_pitch_link"/>
            <body name="right_shoulder_roll_link" pos="5e-05 -0.1012 0" euler="-0.2 0 0">
              <inertial pos="0 -0.00015563 -0.00797243" quat="0.449914 0.545507 0.449914 0.545507" mass="0.229" diaginertia="7.05648e-05 6.60152e-05 5.784e-05"/>
<!--              <joint name="right_shoulder_roll_joint" pos="0 0 0" axis="1 0 0" range="-3.1416 0.2618" actuatorfrcrange="-84 84"/>-->
              <geom type="mesh" contype="0" conaffinity="0" group="1" density="0" rgba="0.75294 0.75294 0.75294 1" mesh="right_shoulder_roll_link"/>
              <geom type="mesh" rgba="0.75294 0.75294 0.75294 1" mesh="right_shoulder_roll_link"/>
              <body name="right_shoulder_yaw_link">
                <inertial pos="-7.8318e-05 0.001011 -0.12915" mass="1.194" diaginertia="0.00412845 0.00411827 0.00084103"/>
<!--                <joint name="right_shoulder_yaw_joint" pos="0 0 0" axis="0 0 1" range="-2.1817 2.1817" actuatorfrcrange="-84 84"/>-->
                <geom type="mesh" contype="0" conaffinity="0" group="1" density="0" rgba="0.75294 0.75294 0.75294 1" mesh="right_shoulder_yaw_link"/>
                <geom type="mesh" rgba="0.75294 0.75294 0.75294 1" mesh="right_shoulder_yaw_link"/>
                <body name="right_elbow_link" pos="0 0 -0.23" euler="0 1.0 0">
                  <inertial pos="0.0167741 0 -0.00133301" quat="0 0.684589 0 0.728929" mass="0.185" diaginertia="0.000124726 0.00011358 7.98035e-05"/>
<!--                  <joint name="right_elbow_joint" pos="0 0 0" axis="0 1 0" range="-0.6981 1.5707" actuatorfrcrange="-37 37"/>-->
                  <geom type="mesh" contype="0" conaffinity="0" group="1" density="0" rgba="0.75294 0.75294 0.75294 1" mesh="right_elbow_link"/>
                  <geom type="mesh" rgba="0.75294 0.75294 0.75294 1" mesh="right_elbow_link"/>
                  <body name="right_wrist_roll_link">
                    <inertial pos="0.0985386 -0.00025438 -0.00071846" quat="0.49661 0.497949 0.510134 0.495166" mass="1.372" diaginertia="0.00443163 0.00434654 0.000486748"/>
<!--                    <joint name="right_wrist_roll_joint" pos="0 0 0" axis="1 0 0" range="-2.0071 2.0071" actuatorfrcrange="-37 37"/>-->
                    <geom type="mesh" contype="0" conaffinity="0" group="1" density="0" rgba="0.75294 0.75294 0.75294 1" mesh="right_wrist_roll_link"/>
                    <geom type="mesh" rgba="0.75294 0.75294 0.75294 1" mesh="right_wrist_roll_link"/>
                    <body name="right_wrist_pitch_link" pos="0.235 0 0">
                      <inertial pos="0.0075268 0 0" quat="0.5 0.5 -0.5 0.5" mass="0.042" diaginertia="1.443e-05 1.052e-05 7.83e-06"/>
<!--                      <joint name="right_wrist_pitch_joint" pos="0 0 0" axis="0 1 0" range="-0.5236 0.5236" actuatorfrcrange="-20 20"/>-->
                      <geom type="mesh" contype="0" conaffinity="0" group="1" density="0" rgba="0.75294 0.75294 0.75294 1" mesh="right_wrist_pitch_link"/>
                      <geom type="mesh" rgba="0.75294 0.75294 0.75294 1" mesh="right_wrist_pitch_link"/>
                      <body name="right_wrist_yaw_link" pos="0.021 0 0">
                        <inertial pos="0.0861973 0.00622963 0.00761411" quat="0.334902 0.565466 0.337436 0.673963" mass="0.53" diaginertia="0.00219004 0.00185458 0.00048651"/>
<!--                        <joint name="right_wrist_yaw_joint" pos="0 0 0" axis="0 0 1" range="-1.1344 1.1344" actuatorfrcrange="-25 25"/>-->
                        <geom type="mesh" contype="0" conaffinity="0" group="1" density="0" rgba="0.75294 0.75294 0.75294 1" mesh="right_wrist_yaw_link"/>
                        <geom pos="0.031 0 0" quat="1 0 0 0" type="mesh" contype="0" conaffinity="0" group="1" density="0" rgba="0.75294 0.75294 0.75294 1" mesh="right_hand_link"/>
                        <geom pos="0.031 0 0" quat="1 0 0 0" type="mesh" rgba="0.75294 0.75294 0.75294 1" mesh="right_hand_link"/>
                      </body>
                    </body>
                  </body>
                </body>
              </body>
            </body>
          </body>
          <body name="head_yaw_link" pos="-0.011001 0 0.50589">
            <inertial pos="-0.0115151 0 0.019677" quat="0.959901 0 -0.28034 0" mass="0.56" diaginertia="0.000485828 0.000458813 0.000216341"/>
<!--            <joint name="head_yaw_joint" pos="0 0 0" axis="0 0 1" range="-0.7854 0.7854"/>-->
            <geom type="mesh" contype="0" conaffinity="0" group="1" density="0" rgba="0.7 0.7 0.8 1" mesh="head_yaw_link"/>
            <geom type="mesh" rgba="0.7 0.7 0.8 1" mesh="head_yaw_link"/>
            <body name="head_pitch_link" pos="-0.0295 0 0.05411">
              <inertial pos="0.0474296 1.03862e-06 0.0192405" quat="0 0.856691 0 0.515831" mass="0.864" diaginertia="0.00488189 0.004848 0.00387314"/>
<!--              <joint name="head_pitch_joint" pos="0 0 0" axis="0 1 0" range="-0.1745 0.2618"/>-->
              <geom type="mesh" contype="0" conaffinity="0" group="1" density="0" rgba="0.7 0.7 0.76 1" mesh="head_pitch_link"/>
              <geom type="mesh" rgba="0.7 0.7 0.76 1" mesh="head_pitch_link"/>
            </body>
          </body>
        </body>
      </body>
    </body>
  </worldbody>
  <actuator>
    <motor name="left_hip_pitch_joint" joint="left_hip_pitch_joint"/>
    <motor name="left_hip_roll_joint" joint="left_hip_roll_joint"/>
    <motor name="left_hip_yaw_joint" joint="left_hip_yaw_joint"/>
    <motor name="left_knee_joint" joint="left_knee_joint"/>
    <motor name="left_ankle_pitch_joint" joint="left_ankle_pitch_joint"/>
    <motor name="left_ankle_roll_joint" joint="left_ankle_roll_joint"/>

    <motor name="right_hip_pitch_joint" joint="right_hip_pitch_joint"/>
    <motor name="right_hip_roll_joint" joint="right_hip_roll_joint"/>
    <motor name="right_hip_yaw_joint" joint="right_hip_yaw_joint"/>
    <motor name="right_knee_joint" joint="right_knee_joint"/>
    <motor name="right_ankle_pitch_joint" joint="right_ankle_pitch_joint"/>
    <motor name="right_ankle_roll_joint" joint="right_ankle_roll_joint"/>

    <motor name="waist_roll_joint" joint="waist_roll_joint"/>
    <motor name="waist_yaw_joint" joint="waist_yaw_joint"/>
  </actuator>
  <visual>
    <headlight diffuse="0.6 0.6 0.6" ambient="0.1 0.1 0.1" specular="0.9 0.9 0.9"/>
    <rgba haze="0.15 0.25 0.35 1"/>
    <global azimuth="-140" elevation="-20"/>
  </visual>

  <asset>
    <texture type="skybox" builtin="gradient" rgb1="0 0 0" rgb2="0 0 0" width="800" height="800"/>
    <texture type="2d" name="plane" builtin="checker" mark="edge" rgb1="0.3 0.4 0.5" rgb2="0.1 0.2 0.3" markrgb="0.8 0.8 0.8" width="300" height="300"/>
    <material name="plane" texture="plane" texuniform="true" texrepeat="2 2" reflectance="0.0"/>
  </asset>

  <worldbody>
    <light mode="trackcom" pos="1 0 3.5" dir="0 0 -1" directional="true"/>
    <geom name="floor" size="0 0 0.05" type="plane" material="plane" friction="1.0" />
  </worldbody>
</mujoco>
